# Tratamento de Exceções em C++

## Introdução ao Tratamento de Exceções

O tratamento de exceções é um mecanismo que permite lidar com erros e situações excepcionais de forma organizada e robusta. Em vez de verificar códigos de erro após cada operação, o tratamento de exceções permite separar o código normal do código de tratamento de erros, tornando o programa mais limpo e mais fácil de manter.

No desenvolvimento de cheats para jogos, o tratamento de exceções é particularmente importante, pois você está frequentemente interagindo com memória externa, realizando operações que podem falhar devido a proteções anti-cheat, atualizações do jogo ou outras condições imprevisíveis. Um bom sistema de tratamento de exceções pode ajudar a criar cheats mais robustos que se recuperam de falhas e fornecem feedback útil ao usuário.

Nesta seção, exploraremos como o tratamento de exceções funciona em C++, desde os conceitos básicos até técnicas mais avançadas, sempre com foco em aplicações práticas para o desenvolvimento de cheats para jogos.

## Conceitos Básicos de Tratamento de Exceções

O tratamento de exceções em C++ é baseado em três palavras-chave principais:

1. **try**: Define um bloco de código onde exceções podem ser lançadas.
2. **catch**: Define um bloco de código que é executado quando uma exceção específica é lançada.
3. **throw**: Lança uma exceção quando um problema é detectado.

### Estrutura Básica

A estrutura básica do tratamento de exceções em C++ é:

```cpp
try {
    // Código que pode lançar exceções
    // ...
    if (problema_detectado) {
        throw excecao;  // Lança uma exceção
    }
    // ...
} catch (tipo_excecao e) {
    // Código para lidar com a exceção
    // ...
}
```

### Exemplo Simples

Vamos ver um exemplo simples de tratamento de exceções:

```cpp
#include <iostream>
#include <stdexcept>

int dividir(int a, int b) {
    if (b == 0) {
        throw std::runtime_error("Divisão por zero");
    }
    return a / b;
}

int main() {
    try {
        int resultado = dividir(10, 0);
        std::cout << "Resultado: " << resultado << std::endl;
    } catch (const std::runtime_error& e) {
        std::cerr << "Erro: " << e.what() << std::endl;
    }
    
    std::cout << "Programa continua após o erro" << std::endl;
    
    return 0;
}
```

Neste exemplo:
1. A função `dividir` verifica se o divisor é zero e, se for, lança uma exceção `std::runtime_error`.
2. No `main`, chamamos `dividir` dentro de um bloco `try`.
3. Se uma exceção for lançada, o fluxo de execução é transferido para o bloco `catch` correspondente.
4. O programa continua a execução após o bloco `catch`.

## Tipos de Exceções

C++ permite lançar e capturar exceções de qualquer tipo, mas geralmente usamos classes derivadas de `std::exception` da biblioteca padrão.

### Hierarquia de Exceções Padrão

A biblioteca padrão C++ fornece uma hierarquia de classes de exceção:

- `std::exception`: A classe base para todas as exceções padrão.
  - `std::logic_error`: Exceções que podem ser detectadas antes da execução.
    - `std::invalid_argument`: Argumento inválido.
    - `std::domain_error`: Argumento fora do domínio.
    - `std::length_error`: Tentativa de criar um objeto muito grande.
    - `std::out_of_range`: Acesso fora dos limites.
  - `std::runtime_error`: Exceções que só podem ser detectadas durante a execução.
    - `std::range_error`: Resultado fora de intervalo.
    - `std::overflow_error`: Estouro aritmético.
    - `std::underflow_error`: Estouro aritmético negativo.
    - `std::system_error`: Erro do sistema operacional.

### Exemplo com Diferentes Tipos de Exceções

```cpp
#include <iostream>
#include <stdexcept>
#include <vector>

void verificar_indice(const std::vector<int>& v, size_t indice) {
    if (indice >= v.size()) {
        throw std::out_of_range("Índice fora dos limites");
    }
}

void verificar_valor(int valor) {
    if (valor < 0) {
        throw std::invalid_argument("Valor não pode ser negativo");
    }
}

int main() {
    std::vector<int> numeros = {10, 20, 30, 40, 50};
    
    try {
        verificar_indice(numeros, 10);  // Vai lançar std::out_of_range
        std::cout << "Valor: " << numeros[10] << std::endl;
    } catch (const std::out_of_range& e) {
        std::cerr << "Erro de intervalo: " << e.what() << std::endl;
    }
    
    try {
        verificar_valor(-5);  // Vai lançar std::invalid_argument
    } catch (const std::invalid_argument& e) {
        std::cerr << "Argumento inválido: " << e.what() << std::endl;
    }
    
    return 0;
}
```

## Capturando Múltiplas Exceções

Você pode capturar diferentes tipos de exceções usando múltiplos blocos `catch`:

```cpp
try {
    // Código que pode lançar diferentes tipos de exceções
    // ...
} catch (const std::out_of_range& e) {
    // Lidar com exceção de intervalo
    std::cerr << "Erro de intervalo: " << e.what() << std::endl;
} catch (const std::invalid_argument& e) {
    // Lidar com argumento inválido
    std::cerr << "Argumento inválido: " << e.what() << std::endl;
} catch (const std::exception& e) {
    // Lidar com qualquer outra exceção derivada de std::exception
    std::cerr << "Exceção: " << e.what() << std::endl;
} catch (...) {
    // Lidar com qualquer outro tipo de exceção
    std::cerr << "Exceção desconhecida" << std::endl;
}
```

A ordem dos blocos `catch` é importante: você deve colocar os tipos mais específicos primeiro e os mais gerais depois. O bloco `catch(...)` captura qualquer tipo de exceção e geralmente é colocado por último.

## Relançando Exceções

Às vezes, você pode querer capturar uma exceção, fazer algum processamento e depois relançá-la para ser tratada em um nível superior:

```cpp
try {
    // Código que pode lançar exceções
    // ...
} catch (const std::exception& e) {
    // Faz algum processamento
    std::cerr << "Capturei uma exceção: " << e.what() << std::endl;
    
    // Relança a mesma exceção
    throw;
    
    // Ou lança uma nova exceção
    // throw std::runtime_error("Nova exceção");
}
```

## Exceções Personalizadas

Você pode criar suas próprias classes de exceção derivando de `std::exception` ou de suas subclasses:

```cpp
#include <iostream>
#include <stdexcept>
#include <string>

class MemoryAccessException : public std::runtime_error {
private:
    uintptr_t endereco;
    
public:
    MemoryAccessException(const std::string& mensagem, uintptr_t _endereco)
        : std::runtime_error(mensagem), endereco(_endereco) {
    }
    
    uintptr_t obter_endereco() const {
        return endereco;
    }
};

void ler_memoria(uintptr_t endereco) {
    // Simula uma falha de acesso à memória
    if (endereco == 0 || endereco > 0xFFFFFFFF) {
        throw MemoryAccessException("Falha ao acessar memória", endereco);
    }
    
    // Código para ler memória
    std::cout << "Memória lida com sucesso no endereço 0x" 
              << std::hex << endereco << std::dec << std::endl;
}

int main() {
    try {
        ler_memoria(0);  // Vai lançar MemoryAccessException
    } catch (const MemoryAccessException& e) {
        std::cerr << "Erro: " << e.what() << std::endl;
        std::cerr << "Endereço: 0x" << std::hex << e.obter_endereco() << std::dec << std::endl;
    }
    
    return 0;
}
```

Ao criar exceções personalizadas:
1. Derive de `std::exception` ou de uma de suas subclasses.
2. Sobrescreva o método `what()` ou use a implementação da classe base.
3. Adicione membros e métodos específicos para fornecer informações adicionais sobre o erro.

## Garantia de Exceção

A garantia de exceção refere-se ao estado do programa após uma exceção ser lançada. Existem três níveis de garantia:

1. **Garantia Básica**: O programa permanece em um estado válido, mas não necessariamente no estado esperado.
2. **Garantia Forte**: O programa retorna ao estado exato em que estava antes da operação que lançou a exceção.
3. **Garantia de Não-Lançamento**: A operação nunca lança exceções.

### RAII (Resource Acquisition Is Initialization)

RAII é um idioma de programação C++ que ajuda a garantir que os recursos sejam liberados corretamente, mesmo quando exceções são lançadas. A ideia é vincular a vida útil de um recurso ao tempo de vida de um objeto:

```cpp
#include <iostream>
#include <fstream>
#include <stdexcept>
#include <memory>

class FileHandle {
private:
    std::ifstream file;
    
public:
    FileHandle(const std::string& filename) : file(filename) {
        if (!file.is_open()) {
            throw std::runtime_error("Não foi possível abrir o arquivo: " + filename);
        }
        std::cout << "Arquivo aberto" << std::endl;
    }
    
    ~FileHandle() {
        if (file.is_open()) {
            file.close();
            std::cout << "Arquivo fechado" << std::endl;
        }
    }
    
    std::string read_line() {
        std::string line;
        if (std::getline(file, line)) {
            return line;
        }
        throw std::runtime_error("Falha ao ler linha do arquivo");
    }
};

void processar_arquivo(const std::string& filename) {
    FileHandle file(filename);  // O recurso é adquirido
    
    // Se uma exceção for lançada aqui, o destrutor de FileHandle
    // será chamado automaticamente, fechando o arquivo
    std::cout << "Primeira linha: " << file.read_line() << std::endl;
    
    // O destrutor de FileHandle é chamado quando file sai de escopo,
    // garantindo que o arquivo seja fechado
}

int main() {
    try {
        processar_arquivo("arquivo_inexistente.txt");
    } catch (const std::exception& e) {
        std::cerr << "Erro: " << e.what() << std::endl;
    }
    
    return 0;
}
```

RAII é especialmente útil para gerenciar recursos como:
- Arquivos
- Memória alocada dinamicamente
- Handles de processos
- Conexões de rede
- Mutexes e outros mecanismos de sincronização

## Aplicações em Desenvolvimento de Cheats

O tratamento de exceções é extremamente útil no desenvolvimento de cheats para jogos. Vamos explorar algumas aplicações práticas:

### 1. Manipulação Segura de Memória

```cpp
#include <iostream>
#include <stdexcept>
#include <Windows.h>

class MemoryException : public std::runtime_error {
private:
    uintptr_t endereco;
    DWORD codigo_erro;
    
public:
    MemoryException(const std::string& mensagem, uintptr_t _endereco, DWORD _codigo_erro)
        : std::runtime_error(mensagem), endereco(_endereco), codigo_erro(_codigo_erro) {
    }
    
    uintptr_t obter_endereco() const {
        return endereco;
    }
    
    DWORD obter_codigo_erro() const {
        return codigo_erro;
    }
};

class ProcessHandle {
private:
    HANDLE handle;
    DWORD processo_id;
    
public:
    ProcessHandle(DWORD _processo_id, DWORD acesso = PROCESS_ALL_ACCESS)
        : processo_id(_processo_id), handle(NULL) {
        handle = OpenProcess(acesso, FALSE, processo_id);
        if (handle == NULL) {
            DWORD erro = GetLastError();
            throw MemoryException("Falha ao abrir processo", 0, erro);
        }
    }
    
    ~ProcessHandle() {
        if (handle != NULL) {
            CloseHandle(handle);
            handle = NULL;
        }
    }
    
    HANDLE obter_handle() const {
        return handle;
    }
    
    DWORD obter_processo_id() const {
        return processo_id;
    }
    
    // Impede cópia
    ProcessHandle(const ProcessHandle&) = delete;
    ProcessHandle& operator=(const ProcessHandle&) = delete;
};

template <typename T>
T ler_memoria(const ProcessHandle& processo, uintptr_t endereco) {
    T valor;
    SIZE_T bytes_lidos;
    
    if (!ReadProcessMemory(
        processo.obter_handle(),
        reinterpret_cast<LPCVOID>(endereco),
        &valor,
        sizeof(T),
        &bytes_lidos
    )) {
        DWORD erro = GetLastError();
        throw MemoryException("Falha ao ler memória", endereco, erro);
    }
    
    if (bytes_lidos != sizeof(T)) {
        throw MemoryException("Leitura parcial de memória", endereco, 0);
    }
    
    return valor;
}

template <typename T>
void escrever_memoria(const ProcessHandle& processo, uintptr_t endereco, const T& valor) {
    SIZE_T bytes_escritos;
    
    if (!WriteProcessMemory(
        processo.obter_handle(),
        reinterpret_cast<LPVOID>(endereco),
        &valor,
        sizeof(T),
        &bytes_escritos
    )) {
        DWORD erro = GetLastError();
        throw MemoryException("Falha ao escrever memória", endereco, erro);
    }
    
    if (bytes_escritos != sizeof(T)) {
        throw MemoryException("Escrita parcial de memória", endereco, 0);
    }
}

int main() {
    try {
        // Obtém o ID do processo do jogo (exemplo)
        DWORD processo_id = 1234;  // Substitua pelo ID real
        
        // Abre o processo
        ProcessHandle processo(processo_id);
        
        // Endereço da vida do jogador (exemplo)
        uintptr_t endereco_vida = 0x12345678;
        
        // Lê o valor atual da vida
        int vida = ler_memoria<int>(processo, endereco_vida);
        std::cout << "Vida atual: " << vida << std::endl;
        
        // Modifica a vida
        escrever_memoria<int>(processo, endereco_vida, 999);
        std::cout << "Vida modificada para 999" << std::endl;
        
        // Verifica se a modificação foi bem-sucedida
        vida = ler_memoria<int>(processo, endereco_vida);
        std::cout << "Nova vida: " << vida << std::endl;
        
    } catch (const MemoryException& e) {
        std::cerr << "Erro de memória: " << e.what() << std::endl;
        std::cerr << "Endereço: 0x" << std::hex << e.obter_endereco() << std::dec << std::endl;
        std::cerr << "Código de erro: " << e.obter_codigo_erro() << std::endl;
        
        // Tenta fornecer uma mensagem mais amigável para o código de erro
        char mensagem_erro[256];
        FormatMessageA(
            FORMAT_MESSAGE_FROM_SYSTEM,
            NULL,
            e.obter_codigo_erro(),
            0,
            mensagem_erro,
            sizeof(mensagem_erro),
            NULL
        );
        std::cerr << "Descrição: " << mensagem_erro << std::endl;
    } catch (const std::exception& e) {
        std::cerr << "Erro: " << e.what() << std::endl;
    } catch (...) {
        std::cerr << "Erro desconhecido" << std::endl;
    }
    
    return 0;
}
```

### 2. Sistema de Injeção de DLL com Tratamento de Erros

```cpp
#include <iostream>
#include <stdexcept>
#include <string>
#include <Windows.h>
#include <TlHelp32.h>

class InjecaoException : public std::runtime_error {
private:
    DWORD codigo_erro;
    std::string fase;
    
public:
    InjecaoException(const std::string& mensagem, const std::string& _fase, DWORD _codigo_erro)
        : std::runtime_error(mensagem), fase(_fase), codigo_erro(_codigo_erro) {
    }
    
    std::string obter_fase() const {
        return fase;
    }
    
    DWORD obter_codigo_erro() const {
        return codigo_erro;
    }
};

DWORD obter_processo_id(const std::string& nome_processo) {
    PROCESSENTRY32 entry;
    entry.dwSize = sizeof(PROCESSENTRY32);
    
    HANDLE snapshot = CreateToolhelp32Snapshot(TH32CS_SNAPPROCESS, 0);
    if (snapshot == INVALID_HANDLE_VALUE) {
        DWORD erro = GetLastError();
        throw InjecaoException("Falha ao criar snapshot de processos", "snapshot", erro);
    }
    
    DWORD processo_id = 0;
    BOOL success = Process32First(snapshot, &entry);
    
    while (success) {
        if (_stricmp(entry.szExeFile, nome_processo.c_str()) == 0) {
            processo_id = entry.th32ProcessID;
            break;
        }
        success = Process32Next(snapshot, &entry);
    }
    
    CloseHandle(snapshot);
    
    if (processo_id == 0) {
        throw InjecaoException("Processo não encontrado", "busca", 0);
    }
    
    return processo_id;
}

void injetar_dll(DWORD processo_id, const std::string& caminho_dll) {
    // Abre o processo alvo
    HANDLE processo = OpenProcess(PROCESS_ALL_ACCESS, FALSE, processo_id);
    if (processo == NULL) {
        DWORD erro = GetLastError();
        throw InjecaoException("Fal
(Content truncated due to size limit. Use line ranges to read in chunks)